[2025-08-22 06:21:36] [ERROR] custom_exception.py (line:34) - 
        Error in [E:\LLMOpsPractice\Documentportal\exception\custom_exception.py] at line [30]
        Message: division by zero
        Traceback:
        Traceback (most recent call last):
  File "E:\LLMOpsPractice\Documentportal\exception\custom_exception.py", line 30, in <module>
    a = 1 / 0
        ~~^~~
ZeroDivisionError: division by zero

        
